<?xml version="1.0" encoding="utf-8"?>
<!-- This URDF was automatically created by SolidWorks to URDF Exporter! Originally created by Stephen Brawner (brawner@gmail.com) 
     Commit Version: 1.6.0-4-g7f85cfe  Build Version: 1.6.7995.38578
     For more information, please see http://wiki.ros.org/sw_urdf_exporter -->
<robot
  name="Ass 1">
  <link
    name="mainbody">
    <inertial>
      <origin
        xyz="-2.3726E-06 0.024422 -4.4955E-05"
        rpy="0 0 0" />
      <mass
        value="0.31081" />
      <inertia
        ixx="0.00021208"
        ixy="1.5623E-09"
        ixz="1.4002E-09"
        iyy="0.00027627"
        iyz="5.5833E-08"
        izz="0.00013006" />
    </inertial>
    <visual>
      <origin
        xyz="0 0 0"
        rpy="0 0 0" />
      <geometry>
        <mesh
          filename="package://Ass 1/meshes/mainbody.STL" />
      </geometry>
      <material
        name="">
        <color
          rgba="0.79216 0.81961 0.93333 1" />
      </material>
    </visual>
    <collision>
      <origin
        xyz="0 0 0"
        rpy="0 0 0" />
      <geometry>
        <mesh
          filename="package://Ass 1/meshes/mainbody.STL" />
      </geometry>
    </collision>
  </link>
  <link
    name="bigleg1">
    <inertial>
      <origin
        xyz="-0.00593603004602124 -0.00371266124380118 -0.0227354388062131"
        rpy="0 0 0" />
      <mass
        value="0.0077756412577186" />
      <inertia
        ixx="3.42452671783294E-06"
        ixy="2.09047419934826E-09"
        ixz="1.28015288448736E-08"
        iyy="2.88716179352755E-06"
        iyz="-3.85678009841775E-07"
        izz="5.88343548175121E-07" />
    </inertial>
    <visual>
      <origin
        xyz="0 0 0"
        rpy="0 0 0" />
      <geometry>
        <mesh
          filename="package://Ass 1/meshes/bigleg1.STL" />
      </geometry>
      <material
        name="">
        <color
          rgba="0.792156862745098 0.819607843137255 0.933333333333333 1" />
      </material>
    </visual>
    <collision>
      <origin
        xyz="0 0 0"
        rpy="0 0 0" />
      <geometry>
        <mesh
          filename="package://Ass 1/meshes/bigleg1.STL" />
      </geometry>
    </collision>
  </link>
  <joint
    name="bigleg1"
    type="continuous">
    <origin
      xyz="-0.0633 0.03 0.034"
      rpy="1.1435 0 0" />
    <parent
      link="mainbody" />
    <child
      link="bigleg1" />
    <axis
      xyz="1 0 0" />
  </joint>
  <link
    name="smallleg1">
    <inertial>
      <origin
        xyz="-0.0211574529093844 -0.0568139492111246 0.0636827920263946"
        rpy="0 0 0" />
      <mass
        value="0.0268340222050022" />
      <inertia
        ixx="1.59304666768254E-05"
        ixy="-5.87713304454316E-09"
        ixz="7.15094089048877E-09"
        iyy="9.08764949149615E-06"
        iyz="6.29879914621856E-06"
        izz="7.66324845924581E-06" />
    </inertial>
    <visual>
      <origin
        xyz="0 0 0"
        rpy="0 0 0" />
      <geometry>
        <mesh
          filename="package://Ass 1/meshes/smallleg1.STL" />
      </geometry>
      <material
        name="">
        <color
          rgba="0.792156862745098 0.819607843137255 0.933333333333333 1" />
      </material>
    </visual>
    <collision>
      <origin
        xyz="0 0 0"
        rpy="0 0 0" />
      <geometry>
        <mesh
          filename="package://Ass 1/meshes/smallleg1.STL" />
      </geometry>
    </collision>
  </link>
  <joint
    name="smallleg1"
    type="continuous">
    <origin
      xyz="0 -0.0080582 -0.049346"
      rpy="0.46371 0 0" />
    <parent
      link="bigleg1" />
    <child
      link="smallleg1" />
    <axis
      xyz="1 0 0" />
  </joint>
  <link
    name="tire">
    <inertial>
      <origin
        xyz="-0.0127998786276471 -2.56739074444567E-16 1.5855372570428E-14"
        rpy="0 0 0" />
      <mass
        value="0.0182536050256655" />
      <inertia
        ixx="8.42538899195331E-06"
        ixy="3.26898054208189E-21"
        ixz="8.24022859238445E-21"
        iyy="4.85700908381744E-06"
        iyz="1.48230765769503E-21"
        izz="4.85700908381745E-06" />
    </inertial>
    <visual>
      <origin
        xyz="0 0 0"
        rpy="0 0 0" />
      <geometry>
        <mesh
          filename="package://Ass 1/meshes/tire.STL" />
      </geometry>
      <material
        name="">
        <color
          rgba="0.792156862745098 0.819607843137255 0.933333333333333 1" />
      </material>
    </visual>
    <collision>
      <origin
        xyz="0 0 0"
        rpy="0 0 0" />
      <geometry>
        <mesh
          filename="package://Ass 1/meshes/tire.STL" />
      </geometry>
    </collision>
  </link>
  <joint
    name="tire"
    type="continuous">
    <origin
      xyz="-0.0207 -0.069889 0.078362"
      rpy="0.9162 0 0" />
    <parent
      link="smallleg1" />
    <child
      link="tire" />
    <axis
      xyz="1 0 0" />
  </joint>
  <link
    name="bigleg2">
    <inertial>
      <origin
        xyz="-0.00673551057779109 -0.00267766598095697 0.0132184760765945"
        rpy="0 0 0" />
      <mass
        value="0.0104336042175876" />
      <inertia
        ixx="3.9627706999722E-06"
        ixy="-2.57524715318403E-09"
        ixz="1.27128787263881E-08"
        iyy="3.12290318636105E-06"
        iyz="4.71826248840826E-07"
        izz="8.89279368298612E-07" />
    </inertial>
    <visual>
      <origin
        xyz="0 0 0"
        rpy="0 0 0" />
      <geometry>
        <mesh
          filename="package://Ass 1/meshes/bigleg2.STL" />
      </geometry>
      <material
        name="">
        <color
          rgba="0.792156862745098 0.819607843137255 0.933333333333333 1" />
      </material>
    </visual>
    <collision>
      <origin
        xyz="0 0 0"
        rpy="0 0 0" />
      <geometry>
        <mesh
          filename="package://Ass 1/meshes/bigleg2.STL" />
      </geometry>
    </collision>
  </link>
  <joint
    name="bigleg2"
    type="continuous">
    <origin
      xyz="-0.0665 -0.03 0.0339999999999999"
      rpy="1.83961174262457 0 0" />
    <parent
      link="mainbody" />
    <child
      link="bigleg2" />
    <axis
      xyz="1 0 0" />
  </joint>
  <link
    name="smallleg2">
    <inertial>
      <origin
        xyz="-0.00256417339746258 -0.0349721074842758 -0.0411243573843793"
        rpy="0 0 0" />
      <mass
        value="0.0111561368021954" />
      <inertia
        ixx="1.36906272520063E-05"
        ixy="6.29989896033431E-09"
        ixz="7.40890095823154E-09"
        iyy="7.88908099750088E-06"
        iyz="-6.25728476190009E-06"
        izz="5.86794347028647E-06" />
    </inertial>
    <visual>
      <origin
        xyz="0 0 0"
        rpy="0 0 0" />
      <geometry>
        <mesh
          filename="package://Ass 1/meshes/smallleg2.STL" />
      </geometry>
      <material
        name="">
        <color
          rgba="0.792156862745098 0.819607843137255 0.933333333333333 1" />
      </material>
    </visual>
    <collision>
      <origin
        xyz="0 0 0"
        rpy="0 0 0" />
      <geometry>
        <mesh
          filename="package://Ass 1/meshes/smallleg2.STL" />
      </geometry>
    </collision>
  </link>
  <joint
    name="smallleg2"
    type="continuous">
    <origin
      xyz="0 -0.0099269 0.049005"
      rpy="-0.39991 0 0" />
    <parent
      link="bigleg2" />
    <child
      link="smallleg2" />
    <axis
      xyz="1 0 0" />
  </joint>
  <link
    name="bigleg3">
    <inertial>
      <origin
        xyz="-0.00673551057779109 -0.00267766598095703 0.0132184760765946"
        rpy="0 0 0" />
      <mass
        value="0.0104336042175876" />
      <inertia
        ixx="3.9627706999722E-06"
        ixy="-2.57524715318402E-09"
        ixz="1.27128787263882E-08"
        iyy="3.12290318636105E-06"
        iyz="4.71826248840826E-07"
        izz="8.89279368298612E-07" />
    </inertial>
    <visual>
      <origin
        xyz="0 0 0"
        rpy="0 0 0" />
      <geometry>
        <mesh
          filename="package://Ass 1/meshes/bigleg3.STL" />
      </geometry>
      <material
        name="">
        <color
          rgba="0.792156862745098 0.819607843137255 0.933333333333333 1" />
      </material>
    </visual>
    <collision>
      <origin
        xyz="0 0 0"
        rpy="0 0 0" />
      <geometry>
        <mesh
          filename="package://Ass 1/meshes/bigleg3.STL" />
      </geometry>
    </collision>
  </link>
  <joint
    name="bigleg3"
    type="continuous">
    <origin
      xyz="0.0665 -0.03 0.034"
      rpy="-2.261 0 3.1416" />
    <parent
      link="mainbody" />
    <child
      link="bigleg3" />
    <axis
      xyz="1 0 0" />
  </joint>
  <link
    name="smallleg3">
    <inertial>
      <origin
        xyz="-0.00256417339746262 -0.0349721074842801 -0.0411243573843788"
        rpy="0 0 0" />
      <mass
        value="0.0111561368021954" />
      <inertia
        ixx="1.36906272520063E-05"
        ixy="6.29989896033295E-09"
        ixz="7.40890095822839E-09"
        iyy="7.88908099750087E-06"
        iyz="-6.25728476190009E-06"
        izz="5.86794347028645E-06" />
    </inertial>
    <visual>
      <origin
        xyz="0 0 0"
        rpy="0 0 0" />
      <geometry>
        <mesh
          filename="package://Ass 1/meshes/smallleg3.STL" />
      </geometry>
      <material
        name="">
        <color
          rgba="0.792156862745098 0.819607843137255 0.933333333333333 1" />
      </material>
    </visual>
    <collision>
      <origin
        xyz="0 0 0"
        rpy="0 0 0" />
      <geometry>
        <mesh
          filename="package://Ass 1/meshes/smallleg3.STL" />
      </geometry>
    </collision>
  </link>
  <joint
    name="smallleg3"
    type="continuous">
    <origin
      xyz="0 -0.0099269 0.049005"
      rpy="2.3015 0 0" />
    <parent
      link="bigleg3" />
    <child
      link="smallleg3" />
    <axis
      xyz="1 0 0" />
  </joint>
  <link
    name="bigleg4">
    <inertial>
      <origin
        xyz="-0.00593603004602121 -0.00371266124380117 -0.0227354388062131"
        rpy="0 0 0" />
      <mass
        value="0.00777564125771858" />
      <inertia
        ixx="3.42452671783293E-06"
        ixy="2.09047419934835E-09"
        ixz="1.28015288448735E-08"
        iyy="2.88716179352755E-06"
        iyz="-3.85678009841773E-07"
        izz="5.8834354817512E-07" />
    </inertial>
    <visual>
      <origin
        xyz="0 0 0"
        rpy="0 0 0" />
      <geometry>
        <mesh
          filename="package://Ass 1/meshes/bigleg4.STL" />
      </geometry>
      <material
        name="">
        <color
          rgba="0.792156862745098 0.819607843137255 0.933333333333333 1" />
      </material>
    </visual>
    <collision>
      <origin
        xyz="0 0 0"
        rpy="0 0 0" />
      <geometry>
        <mesh
          filename="package://Ass 1/meshes/bigleg4.STL" />
      </geometry>
    </collision>
  </link>
  <joint
    name="bigleg4"
    type="continuous">
    <origin
      xyz="0.0633 0.03 0.034"
      rpy="-0.66366 0 -3.1416" />
    <parent
      link="mainbody" />
    <child
      link="bigleg4" />
    <axis
      xyz="1 0 0" />
  </joint>
  <link
    name="smallleg4">
    <inertial>
      <origin
        xyz="-0.0211574529093842 -0.0568139492111265 0.0636827920263948"
        rpy="0 0 0" />
      <mass
        value="0.0268340222050022" />
      <inertia
        ixx="1.59304666768253E-05"
        ixy="-5.87713304452877E-09"
        ixz="7.15094089047282E-09"
        iyy="9.08764949149613E-06"
        iyz="6.29879914621856E-06"
        izz="7.66324845924581E-06" />
    </inertial>
    <visual>
      <origin
        xyz="0 0 0"
        rpy="0 0 0" />
      <geometry>
        <mesh
          filename="package://Ass 1/meshes/smallleg4.STL" />
      </geometry>
      <material
        name="">
        <color
          rgba="0.792156862745098 0.819607843137255 0.933333333333333 1" />
      </material>
    </visual>
    <collision>
      <origin
        xyz="0 0 0"
        rpy="0 0 0" />
      <geometry>
        <mesh
          filename="package://Ass 1/meshes/smallleg4.STL" />
      </geometry>
    </collision>
  </link>
  <joint
    name="smallelg4"
    type="continuous">
    <origin
      xyz="0 -0.0080582 -0.049346"
      rpy="-2.3951 0 0" />
    <parent
      link="bigleg4" />
    <child
      link="smallleg4" />
    <axis
      xyz="1 0 0" />
  </joint>
  <link
    name="tire2">
    <inertial>
      <origin
        xyz="-0.0127998786276472 -1.19348975147204E-15 1.68094704822153E-14"
        rpy="0 0 0" />
      <mass
        value="0.0182536050256655" />
      <inertia
        ixx="8.42538899195332E-06"
        ixy="-1.05629166703312E-21"
        ixz="-2.42773145148815E-20"
        iyy="4.85700908381745E-06"
        iyz="7.39942138497095E-22"
        izz="4.85700908381745E-06" />
    </inertial>
    <visual>
      <origin
        xyz="0 0 0"
        rpy="0 0 0" />
      <geometry>
        <mesh
          filename="package://Ass 1/meshes/tire2.STL" />
      </geometry>
      <material
        name="">
        <color
          rgba="0.792156862745098 0.819607843137255 0.933333333333333 1" />
      </material>
    </visual>
    <collision>
      <origin
        xyz="0 0 0"
        rpy="0 0 0" />
      <geometry>
        <mesh
          filename="package://Ass 1/meshes/tire2.STL" />
      </geometry>
    </collision>
  </link>
  <joint
    name="tire2"
    type="continuous">
    <origin
      xyz="-0.0207 -0.069889 0.078362"
      rpy="-1.6536 0 0" />
    <parent
      link="smallleg4" />
    <child
      link="tire2" />
    <axis
      xyz="1 0 0" />
  </joint>
</robot>