<sdf version='1.7'>
  <model name='foc_urdf'>
    <link name='base_link'>
      <inertial>
        <pose>4.1e-05 2e-06 0.020422 0 -0 0</pose>
        <mass>0.31081</mass>
        <inertia>
          <ixx>0</ixx>
          <ixy>0</ixy>
          <ixz>0</ixz>
          <iyy>0</iyy>
          <iyz>0</iyz>
          <izz>0</izz>
        </inertia>
      </inertial>
      <collision name='base_link_collision'>
        <pose>0 0 0 0 -0 0</pose>
        <geometry>
          <mesh>
            <scale>1 1 1</scale>
            <uri>model:/foc_urdf_transmission/meshes/base_link.STL</uri>
          </mesh>
        </geometry>
      </collision>
      <visual name='base_link_visual'>
        <pose>0 0 0 0 -0 0</pose>
        <geometry>
          <mesh>
            <scale>1 1 1</scale>
            <uri>model:/foc_urdf_transmission/meshes/base_link.STL</uri>
          </mesh>
        </geometry>
      </visual>
    </link>
    <joint name='joint01_left' type='revolute'>
      <pose relative_to='base_link'>0.029996 0.0665 0.03 -1.5708 0 0</pose>
      <parent>base_link</parent>
      <child>leg01_left</child>
      <axis>
        <xyz>0 0 -1</xyz>
        <limit>
          <lower>-1.57</lower>
          <upper>1.57</upper>
          <effort>0</effort>
          <velocity>0</velocity>
        </limit>
        <dynamics>
          <spring_reference>0</spring_reference>
          <spring_stiffness>0</spring_stiffness>
        </dynamics>
      </axis>
    </joint>
    <link name='leg01_left'>
      <pose relative_to='joint01_left'>0 0 0 0 -0 0</pose>
      <inertial>
        <pose>0.022145 0.006348 0.002736 0 -0 0</pose>
        <mass>0.00777564</mass>
        <inertia>
          <ixx>7.09482e-07</ixx>
          <ixy>-6.423e-07</ixy>
          <ixz>1.24689e-08</ixz>
          <iyy>2.76602e-06</iyy>
          <iyz>3.5743e-09</iyz>
          <izz>3.42453e-06</izz>
        </inertia>
      </inertial>
      <collision name='leg01_left_collision'>
        <pose>0 0 0 0 -0 0</pose>
        <geometry>
          <mesh>
            <scale>1 1 1</scale>
            <uri>model://foc_urdf_transmission/meshes/leg01_left.STL</uri>
          </mesh>
        </geometry>
      </collision>
      <visual name='leg01_left_visual'>
        <pose>0 0 0 0 -0 0</pose>
        <geometry>
          <mesh>
            <scale>1 1 1</scale>
            <uri>model://foc_urdf_transmission/meshes/leg01_left.STL</uri>
          </mesh>
        </geometry>
      </visual>
    </link>
    <joint name='joint12_left' type='revolute'>
      <pose relative_to='leg01_left'>0.048064 0.013778 0.006 0 -0 0</pose>
      <parent>leg01_left</parent>
      <child>leg12_left</child>
      <axis>
        <xyz>0 0 -1</xyz>
        <limit>
          <lower>-1.57</lower>
          <upper>1.57</upper>
          <effort>0</effort>
          <velocity>0</velocity>
        </limit>
        <dynamics>
          <spring_reference>0</spring_reference>
          <spring_stiffness>0</spring_stiffness>
        </dynamics>
      </axis>
    </joint>
    <link name='leg12_left'>
      <pose relative_to='joint12_left'>0 0 0 0 -0 0</pose>
      <inertial>
        <pose>-0.048689 0.038474 0.002539 0 -0 0</pose>
        <mass>0.0122831</mass>
        <inertia>
          <ixx>5.45667e-06</ixx>
          <ixy>6.16819e-06</ixy>
          <ixz>7.49058e-09</ixz>
          <iyy>8.37933e-06</iyy>
          <iyz>-5.43763e-09</iyz>
          <izz>1.37771e-05</izz>
        </inertia>
      </inertial>
      <collision name='leg12_left_collision'>
        <pose>0 0 0 0 -0 0</pose>
        <geometry>
          <mesh>
            <scale>1 1 1</scale>
            <uri>model://foc_urdf_transmission/meshes/leg12_left.STL</uri>
          </mesh>
        </geometry>
      </collision>
      <visual name='leg12_left_visual'>
        <pose>0 0 0 0 -0 0</pose>
        <geometry>
          <mesh>
            <scale>1 1 1</scale>
            <uri>model://foc_urdf_transmission/meshes/leg12_left.STL</uri>
          </mesh>
        </geometry>
      </visual>
    </link>
    <joint name='joint23_left' type='revolute'>
      <pose relative_to='leg12_left'>-0.082413 0.065063 0 0 -0 0</pose>
      <parent>leg12_left</parent>
      <child>leg23_left</child>
      <axis>
        <xyz>0 0 -1</xyz>
        <limit>
          <lower>-1.57</lower>
          <upper>1.57</upper>
          <effort>0</effort>
          <velocity>0</velocity>
        </limit>
        <dynamics>
          <spring_reference>0</spring_reference>
          <spring_stiffness>0</spring_stiffness>
        </dynamics>
      </axis>
    </joint>
    <link name='leg23_left'>
      <pose relative_to='joint23_left'>0 0 0 0 -0 0</pose>
      <inertial>
        <pose>-0.0366 -0.03554 -0.003436 0 -0 0</pose>
        <mass>0.0111561</mass>
        <inertia>
          <ixx>6.70072e-06</ixx>
          <ixy>-6.33587e-06</ixy>
          <ixz>6.97705e-09</ixz>
          <iyy>7.0563e-06</iyy>
          <iyz>6.77505e-09</iyz>
          <izz>1.36906e-05</izz>
        </inertia>
      </inertial>
      <collision name='leg23_left_collision'>
        <pose>0 0 0 0 -0 0</pose>
        <geometry>
          <mesh>
            <scale>1 1 1</scale>
            <uri>model://foc_urdf_transmission/meshes/leg23_left.STL</uri>
          </mesh>
        </geometry>
      </collision>
      <visual name='leg23_left_visual'>
        <pose>0 0 0 0 -0 0</pose>
        <geometry>
          <mesh>
            <scale>1 1 1</scale>
            <uri>model://foc_urdf_transmission/meshes/leg23_left.STL</uri>
          </mesh>
        </geometry>
      </visual>
    </link>
    <joint name='joint_tire_left' type='revolute'>
      <pose relative_to='leg12_left'>-0.082413 0.065063 0.0095 0 -0 0</pose>
      <parent>leg12_left</parent>
      <child>tire_left</child>
      <axis>
        <xyz>0 0 -1</xyz>
        <limit>
          <lower>-1.57</lower>
          <upper>1.57</upper>
          <effort>0</effort>
          <velocity>0</velocity>
        </limit>
        <dynamics>
          <spring_reference>0</spring_reference>
          <spring_stiffness>0</spring_stiffness>
        </dynamics>
      </axis>
    </joint>
    <link name='tire_left'>
      <pose relative_to='joint_tire_left'>0 0 0 0 -0 0</pose>
      <inertial>
        <pose>0 0 0.013352 0 -0 0</pose>
        <mass>0.0328045</mass>
        <inertia>
          <ixx>6.31446e-06</ixx>
          <ixy>5.29396e-22</ixy>
          <ixz>9.27217e-22</ixz>
          <iyy>6.31446e-06</iyy>
          <iyz>5.35314e-22</iyz>
          <izz>1.05788e-05</izz>
        </inertia>
      </inertial>
      <collision name='tire_left_collision'>
        <pose>0 0 0 0 -0 0</pose>
        <geometry>
          <mesh>
            <scale>1 1 1</scale>
            <uri>model://foc_urdf_transmission/meshes/tire_left.STL</uri>
          </mesh>
        </geometry>
      </collision>
      <visual name='tire_left_visual'>
        <pose>0 0 0 0 -0 0</pose>
        <geometry>
          <mesh>
            <scale>1 1 1</scale>
            <uri>model://foc_urdf_transmission/meshes/tire_left.STL</uri>
          </mesh>
        </geometry>
      </visual>
    </link>
    <joint name='joint01_right' type='revolute'>
      <pose relative_to='base_link'>-0.030004 -0.0665 0.03 -1.5708 0 0</pose>
      <parent>base_link</parent>
      <child>leg1_right</child>
      <axis>
        <xyz>0 0 1</xyz>
        <limit>
          <lower>-1.57</lower>
          <upper>1.57</upper>
          <effort>0</effort>
          <velocity>0</velocity>
        </limit>
        <dynamics>
          <spring_reference>0</spring_reference>
          <spring_stiffness>0</spring_stiffness>
        </dynamics>
      </axis>
    </joint>
    <link name='leg1_right'>
      <pose relative_to='joint01_right'>0 0 0 0 -0 0</pose>
      <inertial>
        <pose>-0.022747 -0.003638 -0.002736 0 -0 0</pose>
        <mass>0.00777564</mass>
        <inertia>
          <ixx>5.85847e-07</ixx>
          <ixy>-3.78157e-07</ixy>
          <ixz>1.28083e-08</ixz>
          <iyy>2.88966e-06</iyy>
          <iyz>2.04862e-09</iyz>
          <izz>3.42453e-06</izz>
        </inertia>
      </inertial>
      <collision name='leg1_right_collision'>
        <pose>0 0 0 0 -0 0</pose>
        <geometry>
          <mesh>
            <scale>1 1 1</scale>
            <uri>model://foc_urdf_transmission/meshes/leg1_right.STL</uri>
          </mesh>
        </geometry>
      </collision>
      <visual name='leg1_right_visual'>
        <pose>0 0 0 0 -0 0</pose>
        <geometry>
          <mesh>
            <scale>1 1 1</scale>
            <uri>model://foc_urdf_transmission/meshes/leg1_right.STL</uri>
          </mesh>
        </geometry>
      </visual>
    </link>
    <joint name='joint12_right' type='revolute'>
      <pose relative_to='leg1_right'>-0.049372 -0.007897 -0.006 0 -0 0</pose>
      <parent>leg1_right</parent>
      <child>leg12_right</child>
      <axis>
        <xyz>0 0 -1</xyz>
        <limit>
          <lower>-1.57</lower>
          <upper>1.57</upper>
          <effort>0</effort>
          <velocity>0</velocity>
        </limit>
        <dynamics>
          <spring_reference>0</spring_reference>
          <spring_stiffness>0</spring_stiffness>
        </dynamics>
      </axis>
    </joint>
    <link name='leg12_right'>
      <pose relative_to='joint12_right'>0 0 0 0 -0 0</pose>
      <inertial>
        <pose>0.041837 0.045832 -0.002539 0 -0 0</pose>
        <mass>0.0122831</mass>
        <inertia>
          <ixx>7.49888e-06</ixx>
          <ixy>-6.31226e-06</ixy>
          <ixz>6.51417e-09</ixz>
          <iyy>6.33712e-06</iyy>
          <iyz>6.57588e-09</iyz>
          <izz>1.37771e-05</izz>
        </inertia>
      </inertial>
      <collision name='leg12_right_collision'>
        <pose>0 0 0 0 -0 0</pose>
        <geometry>
          <mesh>
            <scale>1 1 1</scale>
            <uri>model://foc_urdf_transmission/meshes/leg12_right.STL</uri>
          </mesh>
        </geometry>
      </collision>
      <visual name='leg12_right_visual'>
        <pose>0 0 0 0 -0 0</pose>
        <geometry>
          <mesh>
            <scale>1 1 1</scale>
            <uri>model://foc_urdf_transmission/meshes/leg12_right.STL</uri>
          </mesh>
        </geometry>
      </visual>
    </link>
    <joint name='joint23_right' type='revolute'>
      <pose relative_to='leg12_right'>0.070824 0.077517 0 0 -0 0</pose>
      <parent>leg12_right</parent>
      <child>leg23_right</child>
      <axis>
        <xyz>0 0 1</xyz>
        <limit>
          <lower>-1.57</lower>
          <upper>1.57</upper>
          <effort>0</effort>
          <velocity>0</velocity>
        </limit>
        <dynamics>
          <spring_reference>0</spring_reference>
          <spring_stiffness>0</spring_stiffness>
        </dynamics>
      </axis>
    </joint>
    <link name='leg23_right'>
      <pose relative_to='joint23_right'>0 0 0 0 -0 0</pose>
      <inertial>
        <pose>0.042402 -0.028367 0.003436 0 -0 0</pose>
        <mass>0.0111561</mass>
        <inertia>
          <ixx>4.46727e-06</ixx>
          <ixy>5.86181e-06</ixy>
          <ixz>8.08321e-09</ixz>
          <iyy>9.28975e-06</iyy>
          <iyz>-5.40761e-09</iyz>
          <izz>1.36906e-05</izz>
        </inertia>
      </inertial>
      <collision name='leg23_right_collision'>
        <pose>0 0 0 0 -0 0</pose>
        <geometry>
          <mesh>
            <scale>1 1 1</scale>
            <uri>model://foc_urdf_transmission/meshes/leg23_right.STL</uri>
          </mesh>
        </geometry>
      </collision>
      <visual name='leg23_right_visual'>
        <pose>0 0 0 0 -0 0</pose>
        <geometry>
          <mesh>
            <scale>1 1 1</scale>
            <uri>model://foc_urdf_transmission/meshes/leg23_right.STL</uri>
          </mesh>
        </geometry>
      </visual>
    </link>
    <joint name='joint_tire_right' type='revolute'>
      <pose relative_to='leg12_right'>0.070824 0.077517 -0.0095 0 -0 0</pose>
      <parent>leg12_right</parent>
      <child>tire_right</child>
      <axis>
        <xyz>0 0 1</xyz>
        <limit>
          <lower>-1.57</lower>
          <upper>1.57</upper>
          <effort>0</effort>
          <velocity>0</velocity>
        </limit>
        <dynamics>
          <spring_reference>0</spring_reference>
          <spring_stiffness>0</spring_stiffness>
        </dynamics>
      </axis>
    </joint>
    <link name='tire_right'>
      <pose relative_to='joint_tire_right'>0 0 0 0 -0 0</pose>
      <inertial>
        <pose>-0 -0 -0.013352 0 -0 0</pose>
        <mass>0.0328045</mass>
        <inertia>
          <ixx>6.31446e-06</ixx>
          <ixy>-1.05879e-22</ixy>
          <ixz>-6.24939e-22</ixz>
          <iyy>6.31446e-06</iyy>
          <iyz>-1.02417e-20</iyz>
          <izz>1.05788e-05</izz>
        </inertia>
      </inertial>
      <collision name='tire_right_collision'>
        <pose>0 0 0 0 -0 0</pose>
        <geometry>
          <mesh>
            <scale>1 1 1</scale>
            <uri>model://foc_urdf_transmission/meshes/tire_right.STL</uri>
          </mesh>
        </geometry>
      </collision>
      <visual name='tire_right_visual'>
        <pose>0 0 0 0 -0 0</pose>
        <geometry>
          <mesh>
            <scale>1 1 1</scale>
            <uri>model://foc_urdf_transmission/meshes/tire_right.STL</uri>
          </mesh>
        </geometry>
      </visual>
    </link>
    <joint name='joint04_left' type='revolute'>
      <pose relative_to='base_link'>-0.030004 0.0665 0.03 -1.5708 0 0</pose>
      <parent>base_link</parent>
      <child>leg04_left</child>
      <axis>
        <xyz>0 0 -1</xyz>
        <limit>
          <lower>-1.57</lower>
          <upper>1.57</upper>
          <effort>0</effort>
          <velocity>0</velocity>
        </limit>
        <dynamics>
          <spring_reference>0</spring_reference>
          <spring_stiffness>0</spring_stiffness>
        </dynamics>
      </axis>
    </joint>
    <link name='leg04_left'>
      <pose relative_to='joint04_left'>0 0 0 0 -0 0</pose>
      <inertial>
        <pose>-0.013399 0.001535 0.006736 0 -0 0</pose>
        <mass>0.0104336</mass>
        <inertia>
          <ixx>8.25111e-07</ixx>
          <ixy>2.74179e-07</ixy>
          <ixz>1.28868e-08</ixz>
          <iyy>3.18707e-06</iyy>
          <iyz>-1.47628e-09</iyz>
          <izz>3.96277e-06</izz>
        </inertia>
      </inertial>
      <collision name='leg04_left_collision'>
        <pose>0 0 0 0 -0 0</pose>
        <geometry>
          <mesh>
            <scale>1 1 1</scale>
            <uri>model://foc_urdf_transmission_transmission/meshes/leg04_left.STL</uri>
          </mesh>
        </geometry>
      </collision>
      <visual name='leg04_left_visual'>
        <pose>0 0 0 0 -0 0</pose>
        <geometry>
          <mesh>
            <scale>1 1 1</scale>
            <uri>model://foc_urdf_transmission/meshes/leg04_left.STL</uri>
          </mesh>
        </geometry>
      </visual>
    </link>
    <joint name='joint43_left' type='revolute'>
      <pose relative_to='leg04_left'>-0.049675 0.005691 0.006 0 -0 0</pose>
      <parent>leg04_left</parent>
      <child>leg43_left</child>
      <axis>
        <xyz>0 0 -1</xyz>
        <limit>
          <lower>-1.57</lower>
          <upper>1.57</upper>
          <effort>0</effort>
          <velocity>0</velocity>
        </limit>
        <dynamics>
          <spring_reference>0</spring_reference>
          <spring_stiffness>0</spring_stiffness>
        </dynamics>
      </axis>
    </joint>
    <link name='leg43_left'>
      <pose relative_to='joint43_left'>0 0 0 0 -0 0</pose>
      <inertial>
        <pose>0.038727 0.037609 -0.003436 0 -0 0</pose>
        <mass>0.0111561</mass>
        <inertia>
          <ixx>6.70072e-06</ixx>
          <ixy>-6.33587e-06</ixy>
          <ixz>6.97705e-09</ixz>
          <iyy>7.0563e-06</iyy>
          <iyz>6.77505e-09</iyz>
          <izz>1.36906e-05</izz>
        </inertia>
      </inertial>
      <collision name='leg43_left_collision'>
        <pose>0 0 0 0 -0 0</pose>
        <geometry>
          <mesh>
            <scale>1 1 1</scale>
            <uri>model://foc_urdf_transmission/meshes/leg43_left.STL</uri>
          </mesh>
        </geometry>
      </collision>
      <visual name='leg43_left_visual'>
        <pose>0 0 0 0 -0 0</pose>
        <geometry>
          <mesh>
            <scale>1 1 1</scale>
            <uri>model://foc_urdf_transmission/meshes/leg43_left.STL</uri>
          </mesh>
        </geometry>
      </visual>
    </link>
    <joint name='joint04_right' type='revolute'>
      <pose relative_to='base_link'>0.029996 -0.0665 0.03 -1.5708 0 0</pose>
      <parent>base_link</parent>
      <child>leg04_right</child>
      <axis>
        <xyz>0 0 1</xyz>
        <limit>
          <lower>-1.57</lower>
          <upper>1.57</upper>
          <effort>0</effort>
          <velocity>0</velocity>
        </limit>
        <dynamics>
          <spring_reference>0</spring_reference>
          <spring_stiffness>0</spring_stiffness>
        </dynamics>
      </axis>
    </joint>
    <link name='leg04_right'>
      <pose relative_to='joint04_right'>0 0 0 0 -0 0</pose>
      <inertial>
        <pose>0 0 0 0 -0 0</pose>
        <mass>0.01</mass>
        <inertia>
          <ixx>0</ixx>
          <ixy>0</ixy>
          <ixz>0</ixz>
          <iyy>0</iyy>
          <iyz>0</iyz>
          <izz>0</izz>
        </inertia>
      </inertial>
      <collision name='leg04_right_collision'>
        <pose>0 0 0 0 -0 0</pose>
        <geometry>
          <mesh>
            <scale>1 1 1</scale>
            <uri>model://foc_urdf_transmission/meshes/leg04_right.STL</uri>
          </mesh>
        </geometry>
      </collision>
      <visual name='leg04_right_visual'>
        <pose>0 0 0 0 -0 0</pose>
        <geometry>
          <mesh>
            <scale>1 1 1</scale>
            <uri>model://foc_urdf_transmission/meshes/leg04_right.STL</uri>
          </mesh>
        </geometry>
      </visual>
    </link>
    <joint name='joint43_right' type='revolute'>
      <pose relative_to='leg04_right'>0.048722 0.011234 -0.006 0 -0 0</pose>
      <parent>leg04_right</parent>
      <child>leg43_right</child>
      <axis>
        <xyz>0 0 1</xyz>
        <limit>
          <lower>-1.57</lower>
          <upper>1.57</upper>
          <effort>0</effort>
          <velocity>0</velocity>
        </limit>
        <dynamics>
          <spring_reference>0</spring_reference>
          <spring_stiffness>0</spring_stiffness>
        </dynamics>
      </axis>
    </joint>
    <link name='leg43_right'>
      <pose relative_to='joint43_right'>0 0 0 0 -0 0</pose>
      <inertial>
        <pose>-0.044868 0.030019 0.003436 0 -0 0</pose>
        <mass>0.0111561</mass>
        <inertia>
          <ixx>4.46727e-06</ixx>
          <ixy>5.86181e-06</ixy>
          <ixz>8.08321e-09</ixz>
          <iyy>9.28975e-06</iyy>
          <iyz>-5.40761e-09</iyz>
          <izz>1.36906e-05</izz>
        </inertia>
      </inertial>
      <collision name='leg43_right_collision'>
        <pose>0 0 0 0 -0 0</pose>
        <geometry>
          <mesh>
            <scale>1 1 1</scale>
            <uri>model://foc_urdf_transmission/meshes/leg43_right.STL</uri>
          </mesh>
        </geometry>
      </collision>
      <visual name='leg43_right_visual'>
        <pose>0 0 0 0 -0 0</pose>
        <geometry>
          <mesh>
            <scale>1 1 1</scale>
            <uri>model://foc_urdf_transmission/meshes/leg43_right.STL</uri>
          </mesh>
        </geometry>
      </visual>
    </link>
  </model>
</sdf>
