<?xml version="1.0" encoding="utf-8"?>
<!-- This URDF was automatically created by SolidWorks to URDF Exporter! Originally created by Stephen Brawner (brawner@gmail.com) 
     Commit Version: 1.6.0-4-g7f85cfe  Build Version: 1.6.7995.38578
     For more information, please see http://wiki.ros.org/sw_urdf_exporter -->
<robot
  name="Ass 1.1">
  <link
    name="base_link">
    <inertial>
      <origin
        xyz="4.09841988512367E-05 2.37259713124077E-06 0.0204223779825749"
        rpy="0 0 0" />
      <mass
        value="0.310805030676399" />
      <inertia
        ixx="0.000130060066627176"
        ixy="1.40022801629673E-09"
        ixz="-5.58328344584131E-08"
        iyy="0.000212083252188243"
        iyz="-1.56227645579612E-09"
        izz="0.000276271215536127" />
    </inertial>
    <visual>
      <origin
        xyz="0 0 0"
        rpy="0 0 0" />
      <geometry>
        <mesh
          filename="package://Ass 1.1/meshes/base_link.STL" />
      </geometry>
      <material
        name="">
        <color
          rgba="0.792156862745098 0.819607843137255 0.933333333333333 1" />
      </material>
    </visual>
    <collision>
      <origin
        xyz="0 0 0"
        rpy="0 0 0" />
      <geometry>
        <mesh
          filename="package://Ass 1.1/meshes/base_link.STL" />
      </geometry>
    </collision>
  </link>
  <link
    name="big3">
    <inertial>
      <origin
        xyz="-0.0134070886544285 0.00146559841204751 -0.00673551057779109"
        rpy="0 0 0" />
      <mass
        value="0.0104336042175876" />
      <inertia
        ixx="8.22335040292358E-07"
        ixy="2.61935145644951E-07"
        ixz="-1.2894277006672E-08"
        iyy="3.18984751436731E-06"
        iyz="1.40954031053812E-09"
        izz="3.9627706999722E-06" />
    </inertial>
    <visual>
      <origin
        xyz="0 0 0"
        rpy="0 0 0" />
      <geometry>
        <mesh
          filename="package://Ass 1.1/meshes/big3.STL" />
      </geometry>
      <material
        name="">
        <color
          rgba="0.792156862745098 0.819607843137255 0.933333333333333 1" />
      </material>
    </visual>
    <collision>
      <origin
        xyz="0 0 0"
        rpy="0 0 0" />
      <geometry>
        <mesh
          filename="package://Ass 1.1/meshes/big3.STL" />
      </geometry>
    </collision>
  </link>
  <joint
    name="jointbig3"
    type="revolute">
    <origin
      xyz="-0.030004 -0.0665 0.03"
      rpy="-1.5708 0 0" />
    <parent
      link="base_link" />
    <child
      link="big3" />
    <axis
      xyz="0 0 1" />
    <limit
      lower="0"
      upper="0"
      effort="0"
      velocity="0" />
  </joint>
  <link
    name="small3">
    <inertial>
      <origin
        xyz="0.0394582340714023 0.0368416725480409 0.00243582660253754"
        rpy="0 0 0" />
      <mass
        value="0.0111561368021954" />
      <inertia
        ixx="6.43655255680271E-06"
        ixy="-6.3229370913612E-06"
        ixz="-7.10811673037926E-09"
        iyy="7.32047191098462E-06"
        iyz="-6.63741040365017E-09"
        izz="1.36906272520063E-05" />
    </inertial>
    <visual>
      <origin
        xyz="0 0 0"
        rpy="0 0 0" />
      <geometry>
        <mesh
          filename="package://Ass 1.1/meshes/small3.STL" />
      </geometry>
      <material
        name="">
        <color
          rgba="0.792156862745098 0.819607843137255 0.933333333333333 1" />
      </material>
    </visual>
    <collision>
      <origin
        xyz="0 0 0"
        rpy="0 0 0" />
      <geometry>
        <mesh
          filename="package://Ass 1.1/meshes/small3.STL" />
      </geometry>
    </collision>
  </link>
  <joint
    name="jointsmall3"
    type="revolute">
    <origin
      xyz="-0.049704 0.0054334 -0.005"
      rpy="0 0 0" />
    <parent
      link="big3" />
    <child
      link="small3" />
    <axis
      xyz="0 0 -1" />
    <limit
      lower="0"
      upper="0"
      effort="0"
      velocity="0" />
  </joint>
  <link
    name="big4">
    <inertial>
      <origin
        xyz="0.0224576054646395 0.00513224980073214 -0.00273603004602135"
        rpy="0 0 0" />
      <mass
        value="0.00777564125771859" />
      <inertia
        ixx="6.45714526227384E-07"
        ixy="-5.26632271374529E-07"
        ixz="-1.26450924213408E-08"
        iyy="2.82979081547529E-06"
        iyz="-2.88978559758573E-09"
        izz="3.42452671783293E-06" />
    </inertial>
    <visual>
      <origin
        xyz="0 0 0"
        rpy="0 0 0" />
      <geometry>
        <mesh
          filename="package://Ass 1.1/meshes/big4.STL" />
      </geometry>
      <material
        name="">
        <color
          rgba="0.792156862745098 0.819607843137255 0.933333333333333 1" />
      </material>
    </visual>
    <collision>
      <origin
        xyz="0 0 0"
        rpy="0 0 0" />
      <geometry>
        <mesh
          filename="package://Ass 1.1/meshes/big4.STL" />
      </geometry>
    </collision>
  </link>
  <joint
    name="jointbig4"
    type="revolute">
    <origin
      xyz="0.029996 -0.0665 0.03"
      rpy="-1.5708 0 0" />
    <parent
      link="base_link" />
    <child
      link="big4" />
    <axis
      xyz="0 0 -1" />
    <limit
      lower="0"
      upper="0"
      effort="0"
      velocity="0" />
  </joint>
  <link
    name="small4">
    <inertial>
      <origin
        xyz="-0.0664136970004676 0.0535961162396307 -0.0119574529093842"
        rpy="0 0 0" />
      <mass
        value="0.0268340222050022" />
      <inertia
        ixx="7.02864859087569E-06"
        ixy="6.19420931063004E-06"
        ixz="-6.96177758529783E-09"
        iyy="9.72224935986626E-06"
        iyz="6.10002469626266E-09"
        izz="1.59304666768253E-05" />
    </inertial>
    <visual>
      <origin
        xyz="0 0 0"
        rpy="0 0 0" />
      <geometry>
        <mesh
          filename="package://Ass 1.1/meshes/small4.STL" />
      </geometry>
      <material
        name="">
        <color
          rgba="0.792156862745098 0.819607843137255 0.933333333333333 1" />
      </material>
    </visual>
    <collision>
      <origin
        xyz="0 0 0"
        rpy="0 0 0" />
      <geometry>
        <mesh
          filename="package://Ass 1.1/meshes/small4.STL" />
      </geometry>
    </collision>
  </link>
  <joint
    name="jointsmall4"
    type="revolute">
    <origin
      xyz="0.048743 0.011139 -0.006"
      rpy="0 0 0" />
    <parent
      link="big4" />
    <child
      link="small4" />
    <axis
      xyz="0 0 1" />
    <limit
      lower="0"
      upper="0"
      effort="0"
      velocity="0" />
  </joint>
  <link
    name="tire34">
    <inertial>
      <origin
        xyz="0.00217112730701572 -0.0530017260825686 0.0855001142820936"
        rpy="0 0 0" />
      <mass
        value="6.43417489455155" />
      <inertia
        ixx="0.0380101766979838"
        ixy="0.000437602498857918"
        ixz="6.11058573748003E-05"
        iyy="0.0353911818011722"
        iyz="-1.20645409849835E-05"
        izz="0.0270525455456595" />
    </inertial>
    <visual>
      <origin
        xyz="0 0 0"
        rpy="0 0 0" />
      <geometry>
        <mesh
          filename="package://Ass 1.1/meshes/tire34.STL" />
      </geometry>
      <material
        name="">
        <color
          rgba="1 1 1 1" />
      </material>
    </visual>
    <collision>
      <origin
        xyz="0 0 0"
        rpy="0 0 0" />
      <geometry>
        <mesh
          filename="package://Ass 1.1/meshes/tire34.STL" />
      </geometry>
    </collision>
  </link>
  <joint
    name="jointtire34"
    type="floating">
    <origin
      xyz="-0.081701 0.065954 -0.013"
      rpy="0 0 0" />
    <parent
      link="small4" />
    <child
      link="tire34" />
    <axis
      xyz="0 0 1" />
    <limit
      lower="0"
      upper="0"
      effort="0"
      velocity="0" />
  </joint>
  <link
    name="big1">
    <inertial>
      <origin
        xyz="0.0230137231993178 -0.00102595113315121 0.00273603004602135"
        rpy="0 0 0" />
      <mass
        value="0.00777564125771859" />
      <inertia
        ixx="5.30172326805182E-07"
        ixy="1.07882210026455E-07"
        ixz="1.29582220100487E-08"
        iyy="2.94533301489749E-06"
        iyz="-5.77672469964852E-10"
        izz="3.42452671783293E-06" />
    </inertial>
    <visual>
      <origin
        xyz="0 0 0"
        rpy="0 0 0" />
      <geometry>
        <mesh
          filename="package://Ass 1.1/meshes/big1.STL" />
      </geometry>
      <material
        name="">
        <color
          rgba="0.792156862745098 0.819607843137255 0.933333333333333 1" />
      </material>
    </visual>
    <collision>
      <origin
        xyz="0 0 0"
        rpy="0 0 0" />
      <geometry>
        <mesh
          filename="package://Ass 1.1/meshes/big1.STL" />
      </geometry>
    </collision>
  </link>
  <joint
    name="jointbig1"
    type="revolute">
    <origin
      xyz="0.029996 0.0665 0.03"
      rpy="-1.5708 0 0" />
    <parent
      link="base_link" />
    <child
      link="big1" />
    <axis
      xyz="0 0 -1" />
    <limit
      lower="0"
      upper="0"
      effort="0"
      velocity="0" />
  </joint>
  <link
    name="small1">
    <inertial>
      <origin
        xyz="-0.0583815990055666 0.0622487889263295 0.0119574529093842"
        rpy="0 0 0" />
      <mass
        value="0.0268340222050022" />
      <inertia
        ixx="8.78964937007165E-06"
        ixy="6.32538839065257E-06"
        ixz="6.60032885441986E-09"
        iyy="7.96124858067029E-06"
        iyz="-6.489399622132E-09"
        izz="1.59304666768253E-05" />
    </inertial>
    <visual>
      <origin
        xyz="0 0 0"
        rpy="0 0 0" />
      <geometry>
        <mesh
          filename="package://Ass 1.1/meshes/small1.STL" />
      </geometry>
      <material
        name="">
        <color
          rgba="0.792156862745098 0.819607843137255 0.933333333333333 1" />
      </material>
    </visual>
    <collision>
      <origin
        xyz="0 0 0"
        rpy="0 0 0" />
      <geometry>
        <mesh
          filename="package://Ass 1.1/meshes/small1.STL" />
      </geometry>
    </collision>
  </link>
  <joint
    name="jointsmall1"
    type="revolute">
    <origin
      xyz="0.04995 -0.0022268 0.006"
      rpy="0 0 0" />
    <parent
      link="big1" />
    <child
      link="small1" />
    <axis
      xyz="0 0 1" />
    <limit
      lower="0"
      upper="0"
      effort="0"
      velocity="0" />
  </joint>
  <link
    name="tire12">
    <inertial>
      <origin
        xyz="-0.00889683852979697 -0.050258398320467 -0.0854998857179067"
        rpy="0 0 0" />
      <mass
        value="6.43417489455155" />
      <inertia
        ixx="0.0380101766979838"
        ixy="0.000437602498857918"
        ixz="6.11058573748007E-05"
        iyy="0.0353911818011722"
        iyz="-1.20645409849869E-05"
        izz="0.0270525455456595" />
    </inertial>
    <visual>
      <origin
        xyz="0 0 0"
        rpy="0 0 0" />
      <geometry>
        <mesh
          filename="package://Ass 1.1/meshes/tire12.STL" />
      </geometry>
      <material
        name="">
        <color
          rgba="1 1 1 1" />
      </material>
    </visual>
    <collision>
      <origin
        xyz="0 0 0"
        rpy="0 0 0" />
      <geometry>
        <mesh
          filename="package://Ass 1.1/meshes/tire12.STL" />
      </geometry>
    </collision>
  </link>
  <joint
    name="jointtire12"
    type="floating">
    <origin
      xyz="-0.071841 0.076576 0.013"
      rpy="0 0 0" />
    <parent
      link="small1" />
    <child
      link="tire12" />
    <axis
      xyz="0 0 -1" />
  </joint>
  <link
    name="big2">
    <inertial>
      <origin
        xyz="-0.0129326682114563 0.00382676074840404 0.00673551057779109"
        rpy="0 0 0" />
      <mass
        value="0.0104336042175876" />
      <inertia
        ixx="9.88913738644862E-07"
        ixy="6.59726234163802E-07"
        ixz="1.24380028097185E-08"
        iyy="3.02326881601479E-06"
        iyz="-3.68038985941867E-09"
        izz="3.96277069997219E-06" />
    </inertial>
    <visual>
      <origin
        xyz="0 0 0"
        rpy="0 0 0" />
      <geometry>
        <mesh
          filename="package://Ass 1.1/meshes/big2.STL" />
      </geometry>
      <material
        name="">
        <color
          rgba="0.792156862745098 0.819607843137255 0.933333333333333 1" />
      </material>
    </visual>
    <collision>
      <origin
        xyz="0 0 0"
        rpy="0 0 0" />
      <geometry>
        <mesh
          filename="package://Ass 1.1/meshes/big2.STL" />
      </geometry>
    </collision>
  </link>
  <joint
    name="jointbig2"
    type="revolute">
    <origin
      xyz="-0.030004 0.0665 0.03"
      rpy="-1.5708 0 0" />
    <parent
      link="base_link" />
    <child
      link="big2" />
    <axis
      xyz="0 0 -1" />
    <limit
      lower="0"
      upper="0"
      effort="0"
      velocity="0" />
  </joint>
  <link
    name="small2">
    <inertial>
      <origin
        xyz="0.044243009495417 0.0309324616375522 -0.00243582660253762"
        rpy="0 0 0" />
      <mass
        value="0.0111561368021954" />
      <inertia
        ixx="4.70949583921532E-06"
        ixy="-5.95568885160247E-06"
        ixz="7.97069377777079E-09"
        iyy="9.04752862857196E-06"
        iyz="5.57212535936874E-09"
        izz="1.36906272520062E-05" />
    </inertial>
    <visual>
      <origin
        xyz="0 0 0"
        rpy="0 0 0" />
      <geometry>
        <mesh
          filename="package://Ass 1.1/meshes/small2.STL" />
      </geometry>
      <material
        name="">
        <color
          rgba="0.792156862745098 0.819607843137255 0.933333333333333 1" />
      </material>
    </visual>
    <collision>
      <origin
        xyz="0 0 0"
        rpy="0 0 0" />
      <geometry>
        <mesh
          filename="package://Ass 1.1/meshes/small2.STL" />
      </geometry>
    </collision>
  </link>
  <joint
    name="jointsmall2"
    type="revolute">
    <origin
      xyz="-0.047945 0.014187 0.005"
      rpy="0 0 0" />
    <parent
      link="big2" />
    <child
      link="small2" />
    <axis
      xyz="0 0 -1" />
    <limit
      lower="0"
      upper="0"
      effort="0"
      velocity="0" />
  </joint>
</robot>